<robot xmlns:ns0="http://ros.org/wiki/xacro">


<ns0:include filename="$(find one_dynamixel_simulation)/urdf/one_dynamixel_simulation.material.xacro" />

  <joint name="origin_to_link1" type="fixed">
    <parent link="world" />
    <child link="link1" />
    <axis xyz="0 0 1" />
    <origin xyz="0 0 0.07" rpy="0 0 0" />
  </joint>

  
  <link name="link1">
    <visual>
      <origin xyz="0 0 0" rpy="${pi/2} 0 0" />
      <geometry>
        <mesh filename="file://$(find one_dynamixel_simulation)/meshes/mx-64at_ar.stl" scale="0.001 0.001 0.001" />
      </geometry>
      <material name="grey" />
    </visual>

    <collision>
      <origin xyz="0 0 0" rpy="${pi/2} 0 0" />
      <geometry>
        <mesh filename="file://$(find one_dynamixel_simulation)/meshes/mx-64at_ar.stl" scale="0.001 0.001 0.001" />
      </geometry>
    </collision>

    <inertial>
      <origin xyz="0.1583e-03 -17.0242e-03 1.6784e-03" />
      <mass value="0.1295" />
      <inertia ixx="56457.58e-06" ixy="-652.34e-06" ixz="646.99e-06" iyy="29325.73e-06" iyz="-5892.95e-06" izz="45111.81e-06" />
    </inertial>
  </link>
  <gazebo reference="link1">
        <material>Gazebo/Grey</material>
  </gazebo>
  
  <joint name="joint1" type="revolute">
    <parent link="link1" />
    <child link="link2" />
    <origin xyz="0.0 -0.03 0.0" rpy="0 0 0" />
    <axis xyz="0 -1 0" />
    <limit velocity="6.597" effort="6.0" lower="-${pi}" upper="${pi}" />
    <dynamics damping="1.45" friction="1.45" />
  </joint>
  <gazebo reference="joint1">
      <implicitSpringDamper>true</implicitSpringDamper>
      <springStiffness>0.5</springStiffness>
      <springReference>0.01</springReference>
      <stopErp>0.7</stopErp>
      <stopCfm>0.45</stopCfm>
  </gazebo>
  
  <link name="link2">
    <visual>
      <origin xyz="0 0 0" rpy="${pi} 0 0" />
      <geometry>
        <mesh filename="file://$(find one_dynamixel_simulation)/meshes/hn05_n102.stl" scale="0.001 0.001 0.001" />
      </geometry>
      <material name="grey" />
    </visual>
    
    <collision>
      <origin xyz="0 0 0" rpy="${pi} 0 0" />
      <geometry>
        <mesh filename="file://$(find one_dynamixel_simulation)/meshes/hn05_n102.stl" scale="0.001 0.001 0.001" />
      </geometry>
    </collision>

     <inertial>
      <origin xyz="0 0 0" />
      <mass value="0.003" />
      <inertia ixx="0.000000588" ixy="0.0" ixz="0.0" iyy="0.0000002039" iyz="0.0" izz="0.000000588" />
    </inertial>
  </link>
  <gazebo reference="link2">
        <material>Gazebo/Grey</material>
  </gazebo>

</robot>